Workbook
Name Minus: 'Calendar Days'!$A$1:$C$5479
Name Plus: 'Calendar Days'!$B$1:$C$5479

Sheet Worksheet
A1: Fire Districts of New York Mutual Insurance Company
A2: Underwriting Analysis Worksheet
B4: Insured: | C4: Belgium-Cold Springs Fire District (25) | I4: Customer Since: | K4: 2000
B5: County: | C5: Onondaga
B7: Renewal Date: | C7: 46022 | D7: Valuation Date: | E7: 45929 | G7: Agent: | H7: McNeil & Company, Inc.
A9: Co | B9: Year | C9: VFBL | D9: WC | E9: Total Premium | F9: Losses | G9: LAE | H9: Total Loss/LAE | I9: Loss ratio | J9: POINTS | K9: # Of Claims | L9: P/R
A10: FPI | B10: 2024-2025 | C10: 50894 | D10: 20355 | E10: =SUM(C10:D10)*L10 -> 71249 | F10: 0 | G10: 0 | H10: =SUM(F10:G10) -> 0 | I10: =H10/E10 -> 0 | K10: 0 | L10: 1
A11: FPI | B11: 2023-2024 | C11: 46925 | D11: 15130 | E11: =SUM(C11:D11) -> 62055 | F11: 14030 | G11: 4000 | H11: =SUM(F11:G11) -> 18030 | I11: =H11/E11 -> 0.29054871 | K11: 1
A12: FPI | B12: 2022-2023 | C12: 47183 | D12: 1936 | E12: =SUM(C12:D12) -> 49119 | F12: 1162 | G12: 55 | H12: =SUM(F12:G12) -> 1217 | I12: =H12/E12 -> 0.024776563 | K12: 2
A13: FPI | B13: 2021-2022 | C13: 45921 | D13: 2889 | E13: =SUM(C13:D13) -> 48810 | F13: 6527 | G13: 3250 | H13: =SUM(F13:G13) -> 9777 | I13: =H13/E13 -> 0.20030731 | K13: 1
A14: FPI | B14: 2020-2021 | C14: 46025 | D14: 3337 | E14: =SUM(C14:D14) -> 49362 | F14: 1140 | G14: 44 | H14: =SUM(F14:G14) -> 1184 | I14: =H14/E14 -> 0.023986062 | K14: 2
A15: FPI | B15: 2019-2020 | C15: 50254 | D15: 3709 | E15: =SUM(C15:D15) -> 53963 | F15: 0 | G15: 0 | H15: =SUM(F15:G15) -> 0 | I15: =H15/E15 -> 0 | K15: 0
A17: 5 Yr Totals: | C17: =SUM(C11:C15) -> 236308 | D17: =SUM(D11:D15) -> 27001 | E17: =SUM(E11:E15) -> 263309 | F17: =SUM(F11:F15) -> 22859 | G17: =SUM(G11:G15) -> 7349 | H17: =SUM(H11:H15) -> 30208 | I17: =ROUND(H17/E17,2) -> 0.11 | J17: =IF(I17>-1,VLOOKUP(I17,'Look Up Tables'!$A$6:$C$19,3),0) -> 20 | K17: =SUM(K11:K15) -> 6 | M17: calcu
A19: Population: | C19: 9500 | D19: Sq Mi: | E19: 13.7 | F19: Density: | G19: =+C19/E19 -> 693.43066 | J19: =IF(G19>-1,VLOOKUP(G19,'Look Up Tables'!$A$20:$C$26,3),0) -> 3
A21: Fire Calls: | C21: 269 | D21: EMS Calls: | E21: 669 | F21: Total Calls: | G21: =C21+E21 -> 938 | J21: =IF(G21>-1,VLOOKUP(G21,'Look Up Tables'!$A$29:$C$36,3),0) -> 3
B23: field in table | C23: Motorized Racing Team (Y=1,N=0) | I23: 0 | K23: calcu
C24: # of H&S Officers | I24: 3 | J24: =IF(I24=0,-2,1) -> 1 | K24: calcu
C25: Safety Comm / Procedures (Y=1,N=0) | I25: 1 | J25: =IF(I25=1,1,-2) -> 1 | K25: calcu
C26: Claims per 100k of Premium: | I26: =K17*100000/E17 -> 2.2786916 | J26: =IF(I26>-1,VLOOKUP(I26,'Look Up Tables'!$A$48:$C$63,3),0) -> 2 | K26: calcu
C27: Penalty for lack of cooperation/losses that indicate poor management practices | K27: calcu
G28: Total Points | J28: =SUM(J17:J26) -> 30 | K28: calcu
G29: Company Assignment | J29: =IF(J28>-1,VLOOKUP(J28,'Look Up Tables'!$A$40:$C$44,3),0) -> FPI | K29: calcu | L29: store in another table
B31: Class A: | D31: Class B: | F31: Class C: | H31: Total: | I31: =C31+E31+G31 -> 0
K32: Pts | L32: Co
B33: # of Ambulances: | F33: # of other Vehicles: | K33: 0-14 | L33: FDM
K34: 15-25 | L34: FDI
B35: * Partial year not included in totals. | K35: 26-31 | L35: FPI

Sheet UW Cover
A1: Underwriting Analysis
A3: Name of Insured: | B3: =Worksheet!C4 -> Belgium-Cold Springs Fire District (25)
A4: Renewal Effective: | B4: =Worksheet!C7 -> 46022
A5: Expiring Total Premium: | B5: =Worksheet!E10 -> 71249
A8: U/W Year | B8: Mod. Factor | C8: Co.
A9: Exp. Mod - 2025 | B9: 1.17 | C9: =Worksheet!J29 -> FPI
A10: Exp. Mod - 2024 | B10: 1.49 | C10: =Worksheet!A10 -> FPI | E10: EXP Calculations 3 Yr Totals
A11: Exp. Mod - 2023 | B11: 1.07 | C11: =Worksheet!A11 -> FPI | E11: Dropping | G11: Adding
A12: Exp. Mod - 2022 | B12: 0.87 | C12: =Worksheet!A12 -> FPI | E12: 0 | G12: 0
A13: Exp. Mod - 2021 | B13: 0.77 | C13: =Worksheet!A13 -> FPI | E13: Difference | H13: =G12-E12 -> 0
A14: Exp. Mod - 2020 | B14: 0.78 | C14: =Worksheet!A14 -> FPI
A15: Exp. Mod - 2019 | B15: 0.81 | C15: =Worksheet!A15 -> FPI
A18: 5 year Loss Ratio: | B18: =Worksheet!I17 -> 0.11 | D18: Renewal Co Assignment: | H18: =Worksheet!J29 -> FPI
A20: County: | B20: =Worksheet!C5 -> Onondaga | D20: Agent: | E20: =Worksheet!H7 -> McNeil & Company, Inc.
A22: Notable Claims:
A23: Claim# | B23: DOL | C23: Status | D23: Description | E23: Incurred | F23: Location
A31: General Comments: This is a VFBL and WC account with a 5 yr loss ratio of 11%. Belgium Cold Springs FD is located in the Town of Lysander in Onondaga County, NY. Per the 2018 Onondaga Planning Agency FD breakdown, the population served by Belgium Cold Springs FD is 9,342. Based on the 2025 renewal application, the population served is 12,179 which falls within a different rating tier as the Onondaga Planning Agency. The 2024 town assessor rolls for the Town of Lysander shows that Belgium-Cold Springs FD serves 4,494 parcels out of the total 11,011 parcels in the Town (41%). We can estimate the population served by taking 41% of the total town population which is 23,074 per the 2020 census. 41% of 23,074 = 9460, which is within the same rating tier as the expiring population and the Onondaga Planning Agency estimate. I spoke to the insured on 10/1/2025 (Amy Speach) and she confirmed that the method of calculating the population based on parcels is more accurate than how the FD came up with the 12,179 (she said this was a best guess based on teh total town population and how many other FD's serve the Town) so we should proceed with using the expiring estimate of 9500. Any Speach also confirmed that the FD no longer has a custodial employee. Per the NYCIRB the FD's new community risk reduction specialist employee should be classified as 7710 (paid firefighter). The FD does not have a racing team. They do have 3 health & safety officers and safety procedures in place. The policy is expiring in FPI and rating in to FPI again for the 2025 year (renewal fpi 30 and expiring in fpi -31) - RENEW IN FPI.
A39: Loss Control Information | E39: Racing Team
A40: Last Physical Audit: | E40: Motorized | H40: =IF(Worksheet!I23=0,"No","Yes") -> No
A41: Prepared By: | C41: T.Higgins | E41: Old-Fashioned | H41: No
A42: UW Manager Approval | E42: Annually Compete | H42: No
A43: Edition 130526

Sheet Look Up Tables
A5: Loss Ratios
A6: 0 | B6: 0.1 | C6: 22
A7: 0.11 | B7: 0.2 | C7: 20
A8: 0.21 | B8: 0.3 | C8: 18
A9: 0.31 | B9: 0.4 | C9: 16
A10: 0.41 | B10: 0.5 | C10: 14
A11: 0.51 | B11: 0.6 | C11: 12
A12: 0.61 | B12: 0.7 | C12: 10
A13: 0.71 | B13: 0.8 | C13: 8
A14: 0.81 | B14: 0.9 | C14: 6
A15: 0.91 | B15: 1 | C15: 4
A16: 1.01 | B16: 10 | C16: 0
A19: Density
A21: 0 | B21: 500 | C21: 4
A22: 501 | B22: 1500 | C22: 3
A23: 1501 | B23: 3000 | C23: 2
A24: 3001 | B24: 5000 | C24: 1
A25: 5001 | B25: 15000 | C25: 0
A28: # of Calls
A30: 0 | B30: 250 | C30: 5
A31: 251 | B31: 500 | C31: 4
A32: 501 | B32: 1000 | C32: 3
A33: 1001 | B33: 1500 | C33: 2
A34: 1501 | B34: 2000 | C34: 1
A35: 2001 | B35: 10000 | C35: 0
A39: Company
A41: 0 | B41: 14 | C41: FDM
A42: 15 | B42: 25 | C42: FDI
A43: 26 | B43: 31 | C43: FPI
A46: Frequency
A48: 0 | B48: 0.75 | C48: 5
A49: 0.76 | B49: 1.5 | C49: 4
A50: 1.51 | B50: 2.25 | C50: 3
A51: 2.26 | B51: 3 | C51: 2
A52: 3.01 | B52: 3.75 | C52: 1
A53: 3.76 | B53: 4.5 | C53: 0
A54: 4.51 | B54: 5.25 | C54: -1
A55: 5.26 | B55: 6 | C55: -2
A56: 6.01 | B56: 6.75 | C56: -3
A57: 6.76 | B57: 7.5 | C57: -4
...

Sheet Calendar Days
A1: 41640 | B1: =A1-365 -> 41275 | C1: 1
A2: =A1+1 -> 41641 | B2: =B1+1 -> 41276 | C2: =C1+1 -> 2
A3: =A2+1 -> 41642 | B3: =B2+1 -> 41277 | C3: =C2+1 -> 3
A4: =A3+1 -> 41643 | B4: =B3+1 -> 41278 | C4: =C3+1 -> 4
A5: =A4+1 -> 41644 | B5: =B4+1 -> 41279 | C5: =C4+1 -> 5
A6: =A5+1 -> 41645 | B6: =B5+1 -> 41280 | C6: =C5+1 -> 6
A7: =A6+1 -> 41646 | B7: =B6+1 -> 41281 | C7: =C6+1 -> 7
A8: =A7+1 -> 41647 | B8: =B7+1 -> 41282 | C8: =C7+1 -> 8
A9: =A8+1 -> 41648 | B9: =B8+1 -> 41283 | C9: =C8+1 -> 9
A10: =A9+1 -> 41649 | B10: =B9+1 -> 41284 | C10: =C9+1 -> 10
A11: =A10+1 -> 41650 | B11: =B10+1 -> 41285 | C11: =C10+1 -> 11
A12: =A11+1 -> 41651 | B12: =B11+1 -> 41286 | C12: =C11+1 -> 12
A13: =A12+1 -> 41652 | B13: =B12+1 -> 41287 | C13: =C12+1 -> 13
... A5479: =A5478+1 -> 47118 | B5479: =B5478+1 -> 46753 | C5479: =C5478+1 -> 5479
